問題のプログラムでは`Hash#new`メソッドの引数にブロックを指定しています。  
ブロックでは、キーが存在しない場合に例外`KeyError`を返すよう設定されています。  
下記のようにHashに存在しないキー`:a`を参照しようとすると例外が発生します。

```ruby
hash[:a] # => KeyError (Key a does not exist in hash {})
```

**エラーにならない場合**

```ruby
hash[:a] = 1 # 参照先であるhash[:a]に値が代入されている場合例外は発生しない
hash.default = nil # デフォルト値をnilに更新しているので例外は発生しない
hash.default_proc = nil　# デフォルト値をnilに更新しているので例外は発生しない
```

**エラーが発生する場合**

`Hash#default_proc`メソッドは`Hash`オブジェクトに設定されたブロック形式のデフォルト値を返します。  
`Hash`オブジェクトがデフォルト値を返す`Proc`を持たない場合は`nil`を返します。

```ruby
proc = hash.default_proc # ここでデフォルト値に設定されたブロックの内容を参照しそれを変数procに代入しています

# callメソッドで意図的にブロックを呼び出し設定された例外を発生させています
proc.call(1, 2) # => KeyError (Key 2 does not exist in hash 1)
```