1回目の`begin`節での処理は、`count`が`0`なので、例外`ZeroDivisionError`が発生し、`rescue ZeroDivisionError`で捕捉されます。  
捕捉した`resuce`内で`count`変数は自己代入され保持する値は`3`となり、`retry`で再度`begin`節の処理を実行します。  
2度目の`begin`節の処理は、`1 / 3`となり例外は発生せず、`else`節が実行されます。  
`ensure`節は例外発生の有無に関わらず必ず実行されるので実行結果は下記のようになります。

```ruby
4
count: 3
```

`rescue`節で捕捉後`retry`で再度`begin`節の処理が実行されるので、1回目の例外捕捉時に`else`節、`ensure`節は実行されません。